<?xml version="1.0" encoding="UTF-8"?>
<testng-results skipped="0" failed="1" ignored="0" total="2" passed="1">
  <reporter-output>
  </reporter-output>
  <suite name="Default suite" duration-ms="99" started-at="2019-09-30T12:48:38 IST" finished-at="2019-09-30T12:48:38 IST">
    <groups>
    </groups>
    <test name="Default test" duration-ms="99" started-at="2019-09-30T12:48:38 IST" finished-at="2019-09-30T12:48:38 IST">
      <class name="com.qa.test.DemoTest">
        <test-method status="FAIL" signature="sub()[pri:0, instance:com.qa.test.DemoTest@6ddf90b0]" name="sub" duration-ms="18" started-at="2019-09-30T12:48:38 IST" finished-at="2019-09-30T12:48:38 IST">
          <exception class="java.lang.AssertionError">
            <message>
              <![CDATA[expected [-10] but found [10]]]>
            </message>
            <full-stacktrace>
              <![CDATA[java.lang.AssertionError: expected [-10] but found [10]
at org.testng.Assert.fail(Assert.java:97)
at org.testng.Assert.assertEqualsImpl(Assert.java:136)
at org.testng.Assert.assertEquals(Assert.java:118)
at org.testng.Assert.assertEquals(Assert.java:839)
at org.testng.Assert.assertEquals(Assert.java:849)
at com.qa.test.DemoTest.sub(DemoTest.java:27)
at sun.reflect.NativeMethodAccessorImpl.invoke0(Native Method)
at sun.reflect.NativeMethodAccessorImpl.invoke(Unknown Source)
at sun.reflect.DelegatingMethodAccessorImpl.invoke(Unknown Source)
at java.lang.reflect.Method.invoke(Unknown Source)
at org.testng.internal.MethodInvocationHelper.invokeMethod(MethodInvocationHelper.java:133)
at org.testng.internal.TestInvoker.invokeMethod(TestInvoker.java:584)
at org.testng.internal.TestInvoker.invokeTestMethod(TestInvoker.java:172)
at org.testng.internal.MethodRunner.runInSequence(MethodRunner.java:46)
at org.testng.internal.TestInvoker$MethodInvocationAgent.invoke(TestInvoker.java:804)
at org.testng.internal.TestInvoker.invokeTestMethods(TestInvoker.java:145)
at org.testng.internal.TestMethodWorker.invokeTestMethods(TestMethodWorker.java:146)
at org.testng.internal.TestMethodWorker.run(TestMethodWorker.java:128)
at java.util.ArrayList.forEach(Unknown Source)
at org.testng.TestRunner.privateRun(TestRunner.java:770)
at org.testng.TestRunner.run(TestRunner.java:591)
at org.testng.SuiteRunner.runTest(SuiteRunner.java:402)
at org.testng.SuiteRunner.runSequentially(SuiteRunner.java:396)
at org.testng.SuiteRunner.privateRun(SuiteRunner.java:355)
at org.testng.SuiteRunner.run(SuiteRunner.java:304)
at org.testng.SuiteRunnerWorker.runSuite(SuiteRunnerWorker.java:53)
at org.testng.SuiteRunnerWorker.run(SuiteRunnerWorker.java:96)
at org.testng.TestNG.runSuitesSequentially(TestNG.java:1180)
at org.testng.TestNG.runSuitesLocally(TestNG.java:1102)
at org.testng.TestNG.runSuites(TestNG.java:1032)
at org.testng.TestNG.run(TestNG.java:1000)
at org.testng.remote.AbstractRemoteTestNG.run(AbstractRemoteTestNG.java:115)
at org.testng.remote.RemoteTestNG.initAndRun(RemoteTestNG.java:251)
at org.testng.remote.RemoteTestNG.main(RemoteTestNG.java:77)
]]>
            </full-stacktrace>
          </exception> <!-- java.lang.AssertionError -->
          <reporter-output>
          </reporter-output>
        </test-method> <!-- sub -->
        <test-method status="PASS" signature="sum()[pri:0, instance:com.qa.test.DemoTest@6ddf90b0]" name="sum" duration-ms="2" started-at="2019-09-30T12:48:38 IST" finished-at="2019-09-30T12:48:38 IST">
          <reporter-output>
          </reporter-output>
        </test-method> <!-- sum -->
      </class> <!-- com.qa.test.DemoTest -->
    </test> <!-- Default test -->
  </suite> <!-- Default suite -->
</testng-results>
